1-La fonction main appelle la fonction f.

2-La fonction f essaie de créer un objet A en appelant son constructeur avec l'argument 1. Cela signifie que le constructeur de la classe A sera exécuté.

3-Dans le constructeur de la classe A, il y a une condition qui vérifie si n est égal à 1. Si c'est le cas, un objet de la classe erreur est créé avec er.num initialisé à 999, puis une exception de type erreur est levée en utilisant throw er.

4-L'exception est propagée à l'appelant, c'est-à-dire à la fonction f.

5-Dans la fonction f, une section catch est utilisée pour attraper l'exception de type erreur qui a été levée. Lorsque l'exception est attrapée, le code à l'intérieur du bloc catch de la fonction f est exécuté. Il affiche "dans f : 999" car er.num avait été initialisé à 999 dans le constructeur de la classe A.

6-Après avoir traité l'exception dans la fonction f, le programme revient à la fonction main.

7-Dans la fonction main, une section catch est utilisée pour attraper à nouveau l'exception de type erreur. Le code à l'intérieur du bloc catch de la fonction main est exécuté, affichant "dans main : 999" car l'exception a été propagée de la fonction f.

8-Après avoir traité l'exception dans la fonction main, le programme continue à s'exécuter normalement. Il affiche "suite main" et se termine.